Workbook

Sheet Dashboard
A1: SWIGGY/ZOMATO-STYLE ORDERS — MINI DASHBOARD
A3: Cleaned dataset · June 2024 · Filter by city using the Slicer (add in Excel — see note)
A6: TOTAL ORDERS | E6: AVG DELIVERY TIME (MIN) | I6: TOTAL DELIVERY CHARGES | M6: CITIES COVERED
A8: =COUNTA(Orders_Cleaned!A2:A91) -> 90 | E8: =AVERAGE(Orders_Cleaned!F2:F91) -> 34.244444 | I8: =SUM(Orders_Cleaned!E2:E91) -> 4437.09 | M8: =COUNTA(CitySummary!A2:A6) -> 5
A12: TOP 3 RESTAURANTS BY ORDER COUNT
A14: Rank | B14: Restaurant | C14: Orders
A15: 1 | B15: =INDEX(RestaurantDetails!$B$2:$B$11,MATCH(LARGE(RestaurantDetails!$D$2:$D$11,1),RestaurantDetails!$D$2:$D$11,0)) -> Domino's Pizza | C15: =LARGE(RestaurantDetails!$D$2:$D$11,1) -> 13
A16: 2 | B16: =INDEX(RestaurantDetails!$B$2:$B$11,MATCH(LARGE(RestaurantDetails!$D$2:$D$11,2),RestaurantDetails!$D$2:$D$11,0)) -> Behrouz Biryani | C16: =LARGE(RestaurantDetails!$D$2:$D$11,2) -> 11
A17: 3 | B17: =INDEX(RestaurantDetails!$B$2:$B$11,MATCH(LARGE(RestaurantDetails!$D$2:$D$11,3),RestaurantDetails!$D$2:$D$11,0)) -> Haldiram's | C17: =LARGE(RestaurantDetails!$D$2:$D$11,3) -> 10
A19: NOTE: A live Slicer must be added inside Excel itself (Insert > Slicer, after building a PivotTable/PivotChart from Orders_Cleaned) — it can't be pre-generated in a script. See the markdown guide, Task 5, for the exact steps to wire one City slicer to every visual on this sheet.

Sheet RawOrders
A1: Order ID | B1: Restaurant ID | C1: Delivery Date | D1: Delivery Partner | E1: Delivery Charges (₹) | F1: Delivery Time (mins)
A2: 4020 | B2: R108 | C2: 09/06/2024 | E2: 56.62 | F2: 36
A3: 4063 | B3: R102 | C3: 24/06/2024 | D3: Sunil Yadav | E3: 34.54 | F3: 42
A4: 4045 | B4: R105 | C4: 29/06/2024 | D4: Rekha Singh | E4: 38.06 | F4: 30
A5: 4034 | B5: R108 | C5: 30-Jun-2024 | E5: 38.71 | F5: 20
A6: 4050 | B6: R102 | C6: 2024-06-09 | D6: Amit Kumar | E6: 47.04 | F6: 35
A7: 4047 | B7: R104 | C7: 11.06.2024 | E7: 35.04 | F7: 45
A8: 4044 | B8: R104 | C8: 23/06/2024 | D8: Farhan Khan | E8: 66.8 | F8: 49
A9: 4086 | B9: R102 | C9: 2024-06-05 | D9: Sunil Yadav | E9: 63.59 | F9: 34
A10: 4035 | B10: R101 | C10: 20/06/2024 | D10: Farhan Khan | E10: 24.04 | F10: 37
A11: 4088 | B11: R103 | C11: 07.06.2024 | E11: 61.11 | F11: 19
A12: 4029 | B12: R103 | C12: 08.06.2024 | D12: Deepa Nair | E12: 59.21 | F12: 22
A13: 4005 | B13: R110 | C13: 01/06/2024 | D13: Amit Kumar | E13: 22.14 | F13: 33
A14: 4076 | B14: R105 | C14: 08.06.2024 | D14: Farhan Khan | E14: 27.62 | F14: 45
A15: 4005 | B15: R110 | C15: 01/06/2024 | D15: Amit Kumar | E15: 22.14 | F15: 33
A16: 4052 | B16: R106 | C16: 23.06.2024 | D16: Rekha Singh | E16: 24.48 | F16: 20
A17: 4067 | B17: R102 | C17: 14/06/2024 | D17: Sunil Yadav | E17: 51.99 | F17: 26
A18: 4012 | B18: R104 | C18: 30/06/2024 | D18: Farhan Khan | E18: 42.53 | F18: 43
A19: 4052 | B19: R106 | C19: 23.06.2024 | D19: Rekha Singh | E19: 24.48 | F19: 20
A20: 4004 | B20: R110 | C20: 13.06.2024 | E20: 64.33 | F20: 28
A21: 4016 | B21: R103 | C21: 2024-06-22 | D21: Farhan Khan | E21: 50.53 | F21: 26
A22: 4078 | B22: R105 | C22: 05/06/2024 | D22: Amit Kumar | E22: 31.65 | F22: 32
A23: 4036 | B23: R106 | C23: 05/06/2024 | D23: Amit Kumar | E23: 47.19 | F23: 41
A24: 4003 | B24: R102 | C24: 15-Jun-2024 | D24: Sunil Yadav | E24: 25.44 | F24: 20
A25: 4028 | B25: R107 | C25: 27.06.2024 | D25: Rekha Singh | E25: 51.2 | F25: 22
A26: 4032 | B26: R106 | C26: 2024-06-17 | D26: Amit Kumar | E26: 41.73 | F26: 46
A27: 4054 | B27: R106 | C27: 10/06/2024 | E27: 28.15 | F27: 47
A28: 4043 | B28: R109 | C28: 01-Jun-2024 | D28: Deepa Nair | E28: 25.26 | F28: 19
A29: 4049 | B29: R104 | C29: 2024-06-05 | D29: Farhan Khan | E29: 41.04 | F29: 20
A30: 4031 | B30: R107 | C30: 2024-06-15 | D30: Amit Kumar | E30: 22.8 | F30: 36
A31: 4014 | B31: R102 | C31: 10-Jun-2024 | D31: Amit Kumar | E31: 77.84 | F31: 25
A32: 4090 | B32: R109 | C32: 21-Jun-2024 | D32: Deepa Nair | E32: 79.92 | F32: 30
A33: 4059 | B33: R103 | C33: 08-Jun-2024 | E33: 40.74 | F33: 51
A34: 4040 | B34: R107 | C34: 19/06/2024 | D34: Deepa Nair | E34: 24.33 | F34: 23
A35: 4009 | B35: R105 | C35: 2024-06-11 | D35: Deepa Nair | E35: 37.34 | F35: 22
A36: 4074 | B36: R107 | C36: 18/06/2024 | D36: Farhan Khan | E36: 25.59 | F36: 28
A37: 4031 | B37: R107 | C37: 2024-06-15 | D37: Amit Kumar | E37: 22.8 | F37: 36
A38: 4081 | B38: R109 | C38: 20-Jun-2024 | E38: 31.86 | F38: 51
A39: 4080 | B39: R110 | C39: 16/06/2024 | D39: Farhan Khan | E39: 63.85 | F39: 25
A40: 4017 | B40: R107 | C40: 21.06.2024 | D40: Amit Kumar | E40: 43.69 | F40: 31
...

Sheet RestaurantDetails
A1: Restaurant ID | B1: Restaurant Name | C1: City | D1: Order Count
A2: R101 | B2: Burger King | C2: Ahmedabad | D2: =COUNTIF(Orders_Cleaned!$B$2:$B$91,A2) -> 7
A3: R102 | B3: Domino's Pizza | C3: Mumbai | D3: =COUNTIF(Orders_Cleaned!$B$2:$B$91,A3) -> 13
A4: R103 | B4: McDonald's | C4: Delhi | D4: =COUNTIF(Orders_Cleaned!$B$2:$B$91,A4) -> 8
A5: R104 | B5: KFC | C5: Bangalore | D5: =COUNTIF(Orders_Cleaned!$B$2:$B$91,A5) -> 9
A6: R105 | B6: Pizza Hut | C6: Pune | D6: =COUNTIF(Orders_Cleaned!$B$2:$B$91,A6) -> 8
A7: R106 | B7: Subway | C7: Ahmedabad | D7: =COUNTIF(Orders_Cleaned!$B$2:$B$91,A7) -> 7
A8: R107 | B8: Behrouz Biryani | C8: Mumbai | D8: =COUNTIF(Orders_Cleaned!$B$2:$B$91,A8) -> 11
A9: R108 | B9: Wow! Momo | C9: Delhi | D9: =COUNTIF(Orders_Cleaned!$B$2:$B$91,A9) -> 8
A10: R109 | B10: Barbeque Nation | C10: Bangalore | D10: =COUNTIF(Orders_Cleaned!$B$2:$B$91,A10) -> 9
A11: R110 | B11: Haldiram's | C11: Pune | D11: =COUNTIF(Orders_Cleaned!$B$2:$B$91,A11) -> 10

Sheet Orders_Cleaned
A1: Order ID | B1: Restaurant ID | C1: Delivery Date | D1: Delivery Partner | E1: Delivery Charges (₹) | F1: Delivery Time (mins) | G1: Restaurant Name | H1: City | I1: Day of Week
A2: 4001 | B2: R108 | C2: 45471 | D2: Farhan Khan | E2: 50.47 | F2: 55 | G2: =VLOOKUP(B2,RestaurantDetails!$A$2:$C$11,2,FALSE()) -> Wow! Momo | H2: =VLOOKUP(B2,RestaurantDetails!$A$2:$C$11,3,FALSE()) -> Delhi | I2: =TEXT(C2,"dddd") -> Friday
A3: 4002 | B3: R104 | C3: 45449 | D3: Unassigned | E3: 56.84 | F3: 29 | G3: =VLOOKUP(B3,RestaurantDetails!$A$2:$C$11,2,FALSE()) -> KFC | H3: =VLOOKUP(B3,RestaurantDetails!$A$2:$C$11,3,FALSE()) -> Bangalore | I3: =TEXT(C3,"dddd") -> Thursday
A4: 4003 | B4: R102 | C4: 45458 | D4: Sunil Yadav | E4: 25.44 | F4: 20 | G4: =VLOOKUP(B4,RestaurantDetails!$A$2:$C$11,2,FALSE()) -> Domino's Pizza | H4: =VLOOKUP(B4,RestaurantDetails!$A$2:$C$11,3,FALSE()) -> Mumbai | I4: =TEXT(C4,"dddd") -> Saturday
A5: 4004 | B5: R110 | C5: 45456 | D5: Unassigned | E5: 64.33 | F5: 28 | G5: =VLOOKUP(B5,RestaurantDetails!$A$2:$C$11,2,FALSE()) -> Haldiram's | H5: =VLOOKUP(B5,RestaurantDetails!$A$2:$C$11,3,FALSE()) -> Pune | I5: =TEXT(C5,"dddd") -> Thursday
A6: 4005 | B6: R110 | C6: 45444 | D6: Amit Kumar | E6: 22.14 | F6: 33 | G6: =VLOOKUP(B6,RestaurantDetails!$A$2:$C$11,2,FALSE()) -> Haldiram's | H6: =VLOOKUP(B6,RestaurantDetails!$A$2:$C$11,3,FALSE()) -> Pune | I6: =TEXT(C6,"dddd") -> Saturday
A7: 4006 | B7: R110 | C7: 45444 | D7: Rekha Singh | E7: 46.43 | F7: 30 | G7: =VLOOKUP(B7,RestaurantDetails!$A$2:$C$11,2,FALSE()) -> Haldiram's | H7: =VLOOKUP(B7,RestaurantDetails!$A$2:$C$11,3,FALSE()) -> Pune | I7: =TEXT(C7,"dddd") -> Saturday
A8: 4007 | B8: R109 | C8: 45451 | D8: Farhan Khan | E8: 20.28 | F8: 23 | G8: =VLOOKUP(B8,RestaurantDetails!$A$2:$C$11,2,FALSE()) -> Barbeque Nation | H8: =VLOOKUP(B8,RestaurantDetails!$A$2:$C$11,3,FALSE()) -> Bangalore | I8: =TEXT(C8,"dddd") -> Saturday
A9: 4008 | B9: R108 | C9: 45464 | D9: Farhan Khan | E9: 79.86 | F9: 23 | G9: =VLOOKUP(B9,RestaurantDetails!$A$2:$C$11,2,FALSE()) -> Wow! Momo | H9: =VLOOKUP(B9,RestaurantDetails!$A$2:$C$11,3,FALSE()) -> Delhi | I9: =TEXT(C9,"dddd") -> Friday
A10: 4009 | B10: R105 | C10: 45454 | D10: Deepa Nair | E10: 37.34 | F10: 22 | G10: =VLOOKUP(B10,RestaurantDetails!$A$2:$C$11,2,FALSE()) -> Pizza Hut | H10: =VLOOKUP(B10,RestaurantDetails!$A$2:$C$11,3,FALSE()) -> Pune | I10: =TEXT(C10,"dddd") -> Tuesday
A11: 4010 | B11: R110 | C11: 45468 | D11: Farhan Khan | E11: 26.47 | F11: 36 | G11: =VLOOKUP(B11,RestaurantDetails!$A$2:$C$11,2,FALSE()) -> Haldiram's | H11: =VLOOKUP(B11,RestaurantDetails!$A$2:$C$11,3,FALSE()) -> Pune | I11: =TEXT(C11,"dddd") -> Tuesday
A12: 4011 | B12: R107 | C12: 45446 | D12: Unassigned | E12: 61.09 | F12: 31 | G12: =VLOOKUP(B12,RestaurantDetails!$A$2:$C$11,2,FALSE()) -> Behrouz Biryani | H12: =VLOOKUP(B12,RestaurantDetails!$A$2:$C$11,3,FALSE()) -> Mumbai | I12: =TEXT(C12,"dddd") -> Monday
A13: 4012 | B13: R104 | C13: 45473 | D13: Farhan Khan | E13: 42.53 | F13: 43 | G13: =VLOOKUP(B13,RestaurantDetails!$A$2:$C$11,2,FALSE()) -> KFC | H13: =VLOOKUP(B13,RestaurantDetails!$A$2:$C$11,3,FALSE()) -> Bangalore | I13: =TEXT(C13,"dddd") -> Sunday
... A91: 4090 | B91: R109 | C91: 45464 | D91: Deepa Nair | E91: 79.92 | F91: 30 | G91: =VLOOKUP(B91,RestaurantDetails!$A$2:$C$11,2,FALSE()) -> Barbeque Nation | H91: =VLOOKUP(B91,RestaurantDetails!$A$2:$C$11,3,FALSE()) -> Bangalore | I91: =TEXT(C91,"dddd") -> Friday

Sheet CitySummary
A1: City | B1: Total Orders | C1: Total Delivery Charges (₹)
A2: Ahmedabad | B2: =COUNTIF(Orders_Cleaned!$H$2:$H$91,A2) -> 14 | C2: =SUMIF(Orders_Cleaned!$H$2:$H$91,A2,Orders_Cleaned!$E$2:$E$91) -> 598.06
A3: Mumbai | B3: =COUNTIF(Orders_Cleaned!$H$2:$H$91,A3) -> 24 | C3: =SUMIF(Orders_Cleaned!$H$2:$H$91,A3,Orders_Cleaned!$E$2:$E$91) -> 1254.95
A4: Delhi | B4: =COUNTIF(Orders_Cleaned!$H$2:$H$91,A4) -> 16 | C4: =SUMIF(Orders_Cleaned!$H$2:$H$91,A4,Orders_Cleaned!$E$2:$E$91) -> 784.84
A5: Bangalore | B5: =COUNTIF(Orders_Cleaned!$H$2:$H$91,A5) -> 18 | C5: =SUMIF(Orders_Cleaned!$H$2:$H$91,A5,Orders_Cleaned!$E$2:$E$91) -> 964.96
A6: Pune | B6: =COUNTIF(Orders_Cleaned!$H$2:$H$91,A6) -> 18 | C6: =SUMIF(Orders_Cleaned!$H$2:$H$91,A6,Orders_Cleaned!$E$2:$E$91) -> 834.28
